<?xml version="1.0" encoding="UTF-8"?>
<!-- Generated by org.testng.reporters.JUnitReportReporter -->
<testsuite hostname="DESKTOP-72M7BDB" failures="1" tests="3" name="parameterization.DataProviderExample" time="17.456" errors="1" timestamp="21 Feb 2021 19:00:45 GMT">
  <testcase classname="parameterization.DataProviderExample" name="logintest" time="2.692"/>
  <testcase classname="parameterization.DataProviderExample" name="logintest" time="6.030">
    <error message="expected [Welcome: Mercury Tours] but found [Login: Mercury Tours]" type="java.lang.AssertionError">
      <![CDATA[java.lang.AssertionError: expected [Welcome: Mercury Tours] but found [Login: Mercury Tours]
	at org.testng.Assert.fail(Assert.java:89)
	at org.testng.Assert.failNotEquals(Assert.java:489)
	at org.testng.Assert.assertEquals(Assert.java:118)
	at org.testng.Assert.assertEquals(Assert.java:171)
	at org.testng.Assert.assertEquals(Assert.java:181)
	at parameterization.DataProviderExample.logintest(DataProviderExample.java:30)
	at java.base/jdk.internal.reflect.NativeMethodAccessorImpl.invoke0(Native Method)
	at java.base/jdk.internal.reflect.NativeMethodAccessorImpl.invoke(NativeMethodAccessorImpl.java:64)
	at java.base/jdk.internal.reflect.DelegatingMethodAccessorImpl.invoke(DelegatingMethodAccessorImpl.java:43)
	at java.base/java.lang.reflect.Method.invoke(Method.java:564)
	at org.testng.internal.MethodInvocationHelper.invokeMethod(MethodInvocationHelper.java:80)
	at org.testng.internal.Invoker.invokeMethod(Invoker.java:715)
	at org.testng.internal.Invoker.invokeTestMethod(Invoker.java:907)
	at org.testng.internal.Invoker.invokeTestMethods(Invoker.java:1237)
	at org.testng.internal.TestMethodWorker.invokeTestMethods(TestMethodWorker.java:127)
	at org.testng.internal.TestMethodWorker.run(TestMethodWorker.java:111)
	at org.testng.TestRunner.privateRun(TestRunner.java:767)
	at org.testng.TestRunner.run(TestRunner.java:617)
	at org.testng.SuiteRunner.runTest(SuiteRunner.java:334)
	at org.testng.SuiteRunner.runSequentially(SuiteRunner.java:329)
	at org.testng.SuiteRunner.privateRun(SuiteRunner.java:291)
	at org.testng.SuiteRunner.run(SuiteRunner.java:240)
	at org.testng.SuiteRunnerWorker.runSuite(SuiteRunnerWorker.java:51)
	at org.testng.SuiteRunnerWorker.run(SuiteRunnerWorker.java:85)
	at org.testng.TestNG.runSuitesSequentially(TestNG.java:1197)
	at org.testng.TestNG.runSuitesLocally(TestNG.java:1122)
	at org.testng.TestNG.run(TestNG.java:1030)
	at org.testng.remote.AbstractRemoteTestNG.run(AbstractRemoteTestNG.java:115)
	at org.testng.remote.RemoteTestNG.initAndRun(RemoteTestNG.java:251)
	at org.testng.remote.RemoteTestNG.main(RemoteTestNG.java:77)
]]>
    </error>
  </testcase> <!-- logintest -->
  <testcase classname="parameterization.DataProviderExample" name="logintest" time="8.734">
    <failure message="
The data provider is trying to pass 1 parameters but the method parameterization.DataProviderExample#logintest takes 2 and TestNG is unable in inject a suitable object" type="org.testng.TestNGException">
      <![CDATA[org.testng.TestNGException: 
The data provider is trying to pass 1 parameters but the method parameterization.DataProviderExample#logintest takes 2 and TestNG is unable in inject a suitable object
	at org.testng.internal.Invoker.injectParameters(Invoker.java:1367)
	at org.testng.internal.Invoker.invokeTestMethods(Invoker.java:1231)
	at org.testng.internal.TestMethodWorker.invokeTestMethods(TestMethodWorker.java:127)
	at org.testng.internal.TestMethodWorker.run(TestMethodWorker.java:111)
	at org.testng.TestRunner.privateRun(TestRunner.java:767)
	at org.testng.TestRunner.run(TestRunner.java:617)
	at org.testng.SuiteRunner.runTest(SuiteRunner.java:334)
	at org.testng.SuiteRunner.runSequentially(SuiteRunner.java:329)
	at org.testng.SuiteRunner.privateRun(SuiteRunner.java:291)
	at org.testng.SuiteRunner.run(SuiteRunner.java:240)
	at org.testng.SuiteRunnerWorker.runSuite(SuiteRunnerWorker.java:51)
	at org.testng.SuiteRunnerWorker.run(SuiteRunnerWorker.java:85)
	at org.testng.TestNG.runSuitesSequentially(TestNG.java:1197)
	at org.testng.TestNG.runSuitesLocally(TestNG.java:1122)
	at org.testng.TestNG.run(TestNG.java:1030)
	at org.testng.remote.AbstractRemoteTestNG.run(AbstractRemoteTestNG.java:115)
	at org.testng.remote.RemoteTestNG.initAndRun(RemoteTestNG.java:251)
	at org.testng.remote.RemoteTestNG.main(RemoteTestNG.java:77)
Caused by: java.lang.ArrayIndexOutOfBoundsException: Index 1 out of bounds for length 1
	at org.testng.internal.Invoker.injectParameters(Invoker.java:1365)
	... 17 more
]]>
    </failure>
  </testcase> <!-- logintest -->
</testsuite> <!-- parameterization.DataProviderExample -->
